Workbook

Sheet Home
B1: POONAWALLA FINCORP LIMITED — FP&A MODEL INDEX
B2: Click any sheet name below to jump to that tab
B4: SECTION / REF | C4: SHEET | D4: WHAT IT COVERS
B5: A — BUSINESS MODEL
B6: A1 | C6: Business Operating Model | D6: End-to-end lending value chain
B7: A2 | C7: FP&A Value Creation Framework | D7: Strategy to value
B8: A3 | C8: Distribution Analytics | D8: Acquisition channels (illustrative)
B9: A4 | C9: Customer Economics | D9: CAC, CLTV, payback (illustrative)
B10: A5 | C10: Customer Analytics | D10: Customer base & cross-sell
B11: B — STRATEGIC FINANCE
B12: B1 | C12: Executive Board Cockpit | D12: One-page board overview + KPI trends
B13: B2 | C13: Business Performance Scorecard | D13: Cited historical KPIs, Q1 FY27, guidance
B14: B3 | C14: Business Drivers | D14: Growth engine
B15: B4 | C15: KPIs & Ratios | D15: Performance (actual + forecast)
B16: C — PLANNING & FORECASTING
B17: C1 | C17: Assumptions | D17: All editable forecast inputs, each with rationale and source
B18: C2 | C18: Revenue Forecast | D18: Growth forecast — Average AUM × Yield
B19: C3 | C19: Funding Forecast | D19: Financing growth — borrowings and cost of funds
B20: C4 | C20: Treasury | D20: Borrowing mix and liquidity position
B21: C5 | C21: Credit Cost Forecast | D21: Risk outlook — GNPA/NNPA/PCR glide path
B22: C6 | C22: Operating Cost Forecast | D22: Efficiency — cost lines on their own drivers
B23: C7 | C23: Regulatory Capital | D23: RWA → CRAR → capital requirement
B24: C8 | C24: CapEx & Depreciation Schedule | D24: Investment planning and net block roll-forward
B25: D — PERFORMANCE & RISK MANAGEMENT
B26: D1 | C26: Portfolio Mix | D26: Product mix & capital allocation decisions
B27: D2 | C27: Product Profitability | D27: Portfolio optimisation — RAROC by product
B28: D3 | C28: Branch Profitability | D28: Network optimisation
B29: D4 | C29: Collections Analytics | D29: Roll rates & recovery (illustrative)
B30: D5 | C30: Digital Transformation | D30: Digital KPIs and cost flow-through
B31: D6 | C31: Enterprise Risk Cockpit | D31: Risk management — RAG status and heat map
B32: D7 | C32: Scenario Analysis | D32: Strategic alternatives — Base / Upside / Downside
B33: E — EXECUTIVE DECISION SUPPORT
B34: E1 | C34: Management Recommendations | D34: Executive actions, each citing its supporting cell
B35: E2 | C35: Value Creation Tracker | D35: Benefits realisation — initiative, owner, impact
B36: F — FINANCIAL STATEMENTS
B37: F1 | C37: Profit & Loss | D37: Consolidated P&L, actuals and forecast
B38: F2 | C38: Balance Sheet | D38: Consolidated Balance Sheet with ties-to-zero check
B39: F3 | C39: Cash Flow Statement | D39: Consolidated Cash Flow with reconciling memo
B40: F4 | C40: Statement of Changes in Equity | D40: Equity movements per annual report
B43: THE CORE DECISION PATH — the 9 tabs that actually drive the recommendation
...

Sheet A - Business Model
B2: A | C2: SECTION A — BUSINESS MODEL | F2: ⌂ Home
C4: How Poonawalla actually operates. This section starts with the customer — not the P&L — and traces the full lending journey through to shareholder value. Everything in Sections B–F is downstream of what happens here.
B6: WHAT THIS SECTION COVERS
C7: • The end-to-end lending value chain: lead generation → acquisition → underwriting → disbursement → collections → cross-sell
C8: • The distribution engine: which channels source customers, at what cost and conversion
C9: • Customer unit economics: acquisition cost, lifetime value, payback period, cross-sell depth
C10: • The conceptual bridge linking business strategy to measurable shareholder value
B12: SHEETS IN THIS SECTION
B13: Ref | C13: Sheet | D13: What it does
B14: A1 | C14: Business Operating Model | D14: The 11-stage lending value chain, each stage showing its live metric and the tab that models it, plus the management flywheel
B15: A2 | C15: FP&A Value Creation Framework | D15: Conceptual loop connecting strategy to shareholder value
B16: A3 | C16: Distribution Analytics | D16: Acquisition channel mix, CAC and conversion by channel (illustrative — channel data not disclosed)
B17: A4 | C17: Customer Economics | D17: CAC, CLTV, CAC payback and CLTV:CAC ratio (illustrative — unit economics not disclosed)
B18: A5 | C18: Customer Analytics | D18: Customer base growth, cross-sell rate, AUM per customer

Sheet Business Operating Model
B1: POONAWALLA FINCORP — BUSINESS OPERATING MODEL | H1: ⌂ Home
B2: The end-to-end lending value chain. Every stage below maps to a tab in this workbook — operations drive the financial outcome, not the reverse.
B4: STAGE | C4: WHAT HAPPENS | D4: KEY METRIC | E4: CURRENT VALUE | F4: WHERE MODELLED
B5: 1. Lead Generation | C5: Demand captured via branch, DSA, digital and partner channels | D5: Channel mix % | E5: See Distribution Analytics | F5: Distribution Analytics
B6: 2. Customer Acquisition | C6: Onboarding, KYC, credit assessment initiation | D6: Cumulative customers (Lakh) | E6: ='Business Drivers'!C9 -> 22 | F6: Customer Economics
B7: 3. Digital Journey | C7: Digital sourcing, straight-through processing, e-KYC | D7: DDP share of disbursement % | E7: ='KPIs & Ratios'!F76 -> 0.82 | F7: Digital Transformation
B8: 4. Credit Underwriting | C8: Risk scoring, policy checks, AI-led decisioning | D8: Approval discipline → GNPA % | E8: ='Business Performance Scorecard'!C192 -> 0.0137 | F8: Credit Cost Forecast
B9: 5. Disbursement | C9: Loan booked and funds released | D9: Total disbursement (₹ Cr) | E9: ='Business Drivers'!D14 -> 50008 | F9: Business Drivers
B10: 6. Portfolio Build | C10: AUM accumulates net of runoff; product mix shifts | D10: AUM (₹ Cr) | E10: ='KPIs & Ratios'!H95 -> 60348 | F10: Portfolio Mix
B11: 7. Collections | C11: EMI recovery, bucket management, early-warning action | D11: Credit cost % of avg AUM | E11: ='KPIs & Ratios'!H43*100 -> 2.4910868 | F11: Collections Analytics
B12: 8. Cross-sell & Retention | C12: Repeat lending to existing base at lower acquisition cost | D12: Cross-sell rate % | E12: ='Customer Analytics'!F8 -> 0.27 | F12: Customer Economics
B13: 9. Funding | C13: Liability raising across banks, NCDs, CP; ALM management | D13: Cost of funds % | E13: ='KPIs & Ratios'!H26*100 -> 7.4796242 | F13: Treasury / Funding Forecast
B14: 10. Profitability | C14: NII after credit cost and opex converts to PAT | D14: PAT (₹ Cr) | E14: ='KPIs & Ratios'!H35 -> 541.81 | F14: Profit & Loss
B15: 11. Shareholder Value | C15: Returns compound into ROE, EPS and book value growth | D15: ROE % | E15: ='KPIs & Ratios'!H34*100 -> 5.8501639 | F15: Board Cockpit
B18: MANAGEMENT FLYWHEEL — how the model self-reinforces
B19: Better Customer Selection | D19: →
B20: Better Portfolio Quality | D20: →
B21: Lower Credit Cost | D21: →
B22: Higher ROE | D22: →
B23: Stronger Capital Base | D23: →
B24: Higher Growth Capacity | D24: →
B25: More Customers ⟳ (loop repeats)

Sheet FP&A Value Creation Framework
B1: FP&A Value Creation Framework | M1: ⌂ Home
B2: The conceptual loop connecting strategy to shareholder value — every tab in this workbook maps to one stage below.
D4: 1. BUSINESS STRATEGY | G4: Diversify product mix (13 loan products), scale secured lending (Gold Loan, LAP), deepen phygital distribution, AI-led underwriting & collections.
D5: ↓
D6: 2. BUSINESS DRIVERS | G6: AUM growth, disbursement volumes, yield on AUM, cost of funds, credit cost, branch/channel productivity, customer acquisition & cross-sell.
D7: ↓
D8: 3. FP&A ANALYSIS | G8: Driver-based forecasting (Driver-Based Forecast tab), product/branch/customer profitability, scenario & sensitivity analysis, budget-vs-actual variance.
D9: ↓
D10: 4. EXECUTIVE INSIGHTS | G10: Distil analysis into a small number of decision-ready insights — e.g. cost-of-borrowing headroom, branch productivity gaps, product-mix profitability skew.
D11: ↓
D12: 5. MANAGEMENT DECISIONS | G12: Capital allocation, pricing & risk-appetite calibration, treasury funding strategy, branch network investment, cost actions (Value Creation Tracker tab).
D13: ↓
D14: 6. BUSINESS PERFORMANCE | G14: Realised AUM growth, NIM, GNPA/NNPA, Cost-to-Income, ROA/ROE — tracked on the Executive Dashboard tab.
D15: ↓
D16: 7. SHAREHOLDER VALUE | G16: Sustainable PAT growth, improving ROE, capital efficiency, stronger credit ratings and lower cost of capital.
D18: ↺ Continuous loop: realised Business Performance and Shareholder Value outcomes feed back into the next Business Strategy review.

Sheet Distribution Analytics
B1: POONAWALLA FINCORP — DISTRIBUTION ANALYTICS | H1: ⌂ Home
B2: ⚠ ILLUSTRATIVE MODEL — Poonawalla does not publicly disclose acquisition-channel mix, channel-level CAC or conversion rates. Only the FY26 branch network (500+, incl. 400 gold-loan branches, AR pg.2) and DDP digital-sourcing share for FY23/FY24 (81%/82%, AR FY24 pg.14) are disclosed. All channel splits below are modelled assumptions.
B4: Acquisition Channel | C4: Share of Sourcing % | D4: Illustrative CAC (₹) | E4: Illustrative Conversion % | F4: Strategic Role
B5: Branch (physical network) | C5: 0.3 | D5: 3200 | E5: 0.22 | F5: Secured products, gold loan, relationship depth
B6: DSA / Channel Partners | C6: 0.22 | D6: 2900 | E6: 0.18 | F6: Volume scale in LAP and business loans
B7: Digital / Direct (DDP) | C7: 0.32 | D7: 1400 | E7: 0.12 | F7: Lowest-cost acquisition; consumer/personal loans
B8: Marketplace / Aggregator | C8: 0.1 | D8: 2100 | E8: 0.15 | F8: Incremental reach, price-sensitive segments
B9: Embedded / Ecosystem Partner | C9: 0.06 | D9: 1800 | E9: 0.25 | F9: Consumer durable, POS-linked lending
B10: TOTAL / BLENDED | C10: =SUM(C5:C9) -> 1 | D10: =SUMPRODUCT(C5:C9,D5:D9)/C10 -> 2364 | E10: =SUMPRODUCT(C5:C9,E5:E9)/C10 -> 0.174
B12: DISCLOSED DISTRIBUTION FACTS (cited)
B13: Branch network (count, FY26) | C13: ='KPIs & Ratios'!H83 -> 500 | F13: AR FY2026 pg.2 — "500+ branches incl. 400 gold loan branches"
B14: Digital (DDP) share of disbursement % (FY24, last disclosed) | C14: ='KPIs & Ratios'!F76 -> 0.82 | F14: AR FY2024 pg.14
B15: Gold-loan dedicated branches opened in FY26 | C15: 400 | F15: AR FY2026 pg.2 — ">90% in Tier II/III locations"
B16: Planned branch additions FY27E | C16: =Assumptions!D13 -> 150 | F16: Assumptions tab (calibrated to management's ~400 gold-loan branch guidance)

Sheet Customer Economics
B1: POONAWALLA FINCORP — CUSTOMER ECONOMICS | H1: ⌂ Home
B2: ⚠ ILLUSTRATIVE MODEL — Only the FY26 customer base (22+ lakh, AR FY26 pg.35) is Company-disclosed. CAC, CLTV, retention, payback and cross-sell economics are NOT publicly disclosed by Poonawalla and are modelled assumptions (yellow cells) for framework demonstration only. Do not present these as company figures.
B4: Metric | C4: FY2024 | D4: FY2025 | E4: FY2026 | F4: Source / Basis
B5: Cumulative Customer Base (Lakh) | C5: ='Customer Analytics'!D5 -> 15 | D5: ='Customer Analytics'!E5 -> 18 | E5: ='Customer Analytics'!F5 -> 22 | F5: FY26 disclosed (AR pg.35); prior years illustrative
B6: New Customers Added (Lakh) | C6: ='Customer Analytics'!D6 -> 4 | D6: ='Customer Analytics'!E6 -> 3 | E6: ='Customer Analytics'!F6 -> 4 | F6: Derived from base movement
B7: Customer Acquisition Cost — CAC (₹) | C7: ='Customer Analytics'!D7 -> 3000 | D7: ='Customer Analytics'!E7 -> 2750 | E7: ='Customer Analytics'!F7 -> 2500 | F7: ILLUSTRATIVE — not disclosed
B8: Average AUM per Customer (₹) | C8: ='Customer Analytics'!D10 -> 166686.67 | D8: ='Customer Analytics'!E10 -> 197950 | E8: ='Customer Analytics'!F10 -> 274309.09 | F8: Derived: AUM ÷ customer base
B9: Cross-sell / Repeat Rate % | C9: ='Customer Analytics'!D8 -> 0.21 | D9: ='Customer Analytics'!E8 -> 0.24 | E9: ='Customer Analytics'!F8 -> 0.27 | F9: ILLUSTRATIVE — not disclosed
B11: DERIVED UNIT ECONOMICS (all illustrative)
B12: Illustrative Revenue per Customer (₹) | E12: =E8*'KPIs & Ratios'!H25 -> 38004.455 | F12: Avg AUM/customer × portfolio yield
B13: Illustrative Contribution per Customer (₹, after funding + credit cost) | E13: =E8*('KPIs & Ratios'!H25-'KPIs & Ratios'!H26-'KPIs & Ratios'!H43) -> 10653.888 | F13: Avg AUM × (yield − cost of funds − credit cost)
B14: Illustrative CAC Payback (years) | E14: =IFERROR(E7/E13,"") -> 0.23465611 | F14: CAC ÷ annual contribution per customer
B15: Illustrative Customer Lifetime Value — CLTV (₹) | E15: =E13*C18 -> 31961.665 | F15: Annual contribution × assumed tenure
B16: Illustrative CLTV : CAC ratio (x) | E16: =IFERROR(E15/E7,"") -> 12.784666 | F16: Target >3x is typical retail-lending benchmark
B18: Assumed average customer tenure (years) | C18: 3

Sheet Customer Analytics
B1: POONAWALLA FINCORP LIMITED — Customer Analytics (Illustrative) | H1: ⌂ Home
B2: ILLUSTRATIVE MODEL: Only the FY2026 customer base (22+ lakh) is company-disclosed (blue, cited). Customer counts for other years, acquisition, retention, CAC and cross-sell figures are illustrative assumptions (yellow) for demonstration purposes only.
B4: Particulars | C4: FY2023 | D4: FY2024 | E4: FY2025 | F4: FY2026
B5: Cumulative Customer Base (Lakh) – illustrative trend to disclosed FY26 actual | C5: 11 | D5: 15 | E5: 18 | F5: 22
B6: New Customers Added (Lakh) | D6: =D5-C5 -> 4 | E6: =E5-D5 -> 3 | F6: =F5-E5 -> 4
B7: Illustrative Customer Acquisition Cost – CAC (₹) | C7: 3200 | D7: 3000 | E7: 2750 | F7: 2500
B8: Illustrative Repeat / Cross-sell Rate % | C8: 0.18 | D8: 0.21 | E8: 0.24 | F8: 0.27
B9: AUM (₹ Cr, Reported/Standalone — linked from Executive Dashboard) | C9: ='Business Performance Scorecard'!E161 -> 16143 | D9: ='Business Performance Scorecard'!F161 -> 25003 | E9: ='Business Performance Scorecard'!G161 -> 35631 | F9: ='Business Performance Scorecard'!H161 -> 60348
B10: Avg. AUM per Customer (₹) | C10: =IFERROR(C9/(C5*100000)*10000000,"") -> 146754.55 | D10: =IFERROR(D9/(D5*100000)*10000000,"") -> 166686.67 | E10: =IFERROR(E9/(E5*100000)*10000000,"") -> 197950 | F10: =IFERROR(F9/(F5*100000)*10000000,"") -> 274309.09

Sheet B - Strategic Finance
B2: B | C2: SECTION B — STRATEGIC FINANCE | F2: ⌂ Home
C4: The board-level view: what happened, why it happened, and what management should do next. This is the section a CFO or VP Finance reads first.
B6: WHAT THIS SECTION COVERS
C7: • A single-page board cockpit: business health RAG, executive narrative, driver engine, decision box and value creation
C8: • The cited disclosure backbone — every historical KPI traced to an annual report page, plus Q1 FY27 actuals and management guidance
C9: • The driver chain that builds AUM from customers, ticket size, cross-sell and portfolio runoff
C10: • The full ratio suite across FY2021–FY2026 actuals and FY2027E–FY2031E forecast
B12: SHEETS IN THIS SECTION
B13: Ref | C13: Sheet | D13: What it does
B14: B1 | C14: Executive Board Cockpit | D14: One-page board overview: business health, narrative, driver engine, CEO heat map, capital allocation, and 10 KPI trend charts (actuals vs forecast)
B15: B2 | C15: Business Performance Scorecard | D15: Cited historical KPIs (FY21–FY26), Q1 FY27 latest-quarter actuals, and management's stated guidance
B16: B3 | C16: Business Drivers | D16: The growth engine — AUM is derived here from customers, loan size, cross-sell and runoff, not assumed
B17: B4 | C17: KPIs & Ratios | D17: ~90 ratios across growth, profitability, asset quality, capital, liquidity, per-share and efficiency — actual and forecast

Sheet Executive Board Cockpit
B1: POONAWALLA FINCORP — EXECUTIVE STRATEGIC FINANCE COCKPIT | I1: ⌂ Home
B2: ="""Driving Sustainable Shareholder Value"" — Board Pack — "&'Scenario Analysis'!C5&" Case Scenario" -> "Driving Sustainable Shareholder Value" — Board Pack — Base Case Scenario
B4: 1. BUSINESS HEALTH (5-SECOND VIEW)
B5: Dimension | C5: KPI | D5: Actual (Q1 FY27 / FY26A) | E5: ="Target (FY27E, "&'Scenario Analysis'!C5&" Case)" -> Target (FY27E, Base Case) | F5: Trend | G5: Status
B6: Growth | C6: AUM (₹ Cr, FY26A vs FY27E target) | D6: ='Balance Sheet'!H14 -> 55951.49 | E6: ='Business Drivers'!D21 -> 86376.468 | F6: =IF(D6>'Balance Sheet'!G14,"▲","▼") -> ▲ | G6: =IF(D6>=E6*0.6,"GREEN",IF(D6>=E6*0.5,"YELLOW","RED")) -> GREEN
B7: Profitability | C7: ROE % (Consolidated) | D7: ='KPIs & Ratios'!H34*100 -> 5.8501639 | E7: ='KPIs & Ratios'!I34*100 -> 12.977669 | F7: =IF(E7>D7,"▲","▼") -> ▲ | G7: =IF(D7>15,"GREEN",IF(D7>8,"YELLOW","RED")) -> RED
B8: Risk | C8: GNPA % | D8: ='Business Performance Scorecard'!C192 -> 0.0137 | E8: ='Credit Cost Forecast'!D6 -> 0.0135 | F8: =IF(D8<'KPIs & Ratios'!H44/100,"▼","▲") -> ▼ | G8: =IF(D8<0.013,"GREEN",IF(D8<0.02,"YELLOW","RED")) -> YELLOW
B9: Efficiency | C9: Cost-to-Income % | D9: ='KPIs & Ratios'!H30*100 -> 52.009442 | E9: ='KPIs & Ratios'!I30*100 -> 41.033648 | F9: =IF(E9<D9,"▲","▼") -> ▲ | G9: =IF(D9<45,"GREEN",IF(D9<55,"YELLOW","RED")) -> YELLOW
B10: Liquidity | C10: LCR % (FY26A) | D10: ='KPIs & Ratios'!H54 -> 181 | E10: >150% target | F10: → | G10: =IF(D10>150,"GREEN",IF(D10>120,"YELLOW","RED")) -> GREEN
B11: Value | C11: Basic EPS (₹) | D11: ='KPIs & Ratios'!H64 -> 6.84 | E11: ='KPIs & Ratios'!I64 -> 13.336712 | F11: =IF(E11>D11,"▲","▼") -> ▲ | G11: =IF(D11>15,"GREEN",IF(D11>5,"YELLOW","RED")) -> YELLOW
B13: 2. EXECUTIVE NARRATIVE
B14: ="AUM reached ₹"&TEXT('Business Performance Scorecard'!H161,"#,##0")&" Cr in FY26 (+"&TEXT('KPIs & Ratios'!H8,"0.0%")&" YoY), driven by continued expansion of secured and unsecured retail lending, while Gross NPA improved to "&TEXT('Business Performance Scorecard'!C192,"0.00%")&" (Q1 FY27). Funding costs remain manageable at "&TEXT('Business Performance Scorecard'!C200,"0.00%")&", though operating efficiency — Cost-to-Income at "&TEXT('KPIs & Ratios'!H30*100,"0.0")&"% — requires further improvement. The Base Case forecast projects PAT growing from ₹"&TEXT('KPIs & Ratios'!H35,"#,##0")&" Cr (FY26A) to ₹"&TEXT('KPIs & Ratios'!I35,"#,##0")&" Cr by FY27E, supported by disciplined capital allocation (₹"&TEXT('Value Creation Tracker'!G10,"#,##0")&" Cr of identified value-creation impact) and enhanced branch productivity." -> AUM reached ₹60,348 Cr in FY26 (+69.4% YoY), driven by continued expansion of secured and unsecured retail lending, while Gross NPA improved to 1.37% (Q1 FY27). Funding costs remain manageable at 7.72%, though operating efficiency — Cost-to-Income at 52.0% — requires further improvement. The Base Case forecast projects PAT growing from ₹542 Cr (FY26A) to ₹1,782 Cr by FY27E, supported by disciplined capital allocation (₹350 Cr of identified value-creation impact) and enhanced branch productivity.
B19: 3. BUSINESS DRIVER ENGINE | D19: Driver Performance
B20: Customer Growth | D20: Driver | E20: Current | F20: Trend | G20: Impact
B21: ↓ | D21: Customers (Lakh) | E21: ='Business Drivers'!C9 -> 22 | F21: =IF('Business Drivers'!C9>'Customer Analytics'!E5,"▲","▼") -> ▲ | G21: High
B22: Disbursement → AUM | D22: AUM Growth % | E22: ='KPIs & Ratios'!H8*100 -> 69.369369 | F22: =IF('KPIs & Ratios'!H8>'KPIs & Ratios'!G8,"▲","▼") -> ▲ | G22: High
B23: ↓ | D23: Yield on Advances % | E23: ='KPIs & Ratios'!H25*100 -> 13.85461 | F23: → | G23: Medium
B24: Interest Income → NII | D24: Credit Cost % | E24: ='KPIs & Ratios'!H43*100 -> 2.4910868 | F24: =IF('KPIs & Ratios'!H43<'KPIs & Ratios'!G43,"▼","▲") -> ▼ | G24: High
B25: ↓
B26: PAT
B27: ↓
B28: ROE → Shareholder Value
B30: 4. CEO HEAT MAP — BUSINESS PRIORITY VIEW
B31: Business Area | C31: Key Metric | D31: Status | E31: Priority
B32: Growth | C32: ="AUM +"&TEXT('KPIs & Ratios'!H8,"0.0%")&" YoY" -> AUM +69.4% YoY | D32: =IF('KPIs & Ratios'!H8>0.2,"GREEN",IF('KPIs & Ratios'!H8>0.1,"YELLOW","RED")) -> GREEN | E32: =IF(D32="GREEN","Maintain",IF(D32="YELLOW","Improve","Immediate Focus")) -> Maintain
B33: Asset Quality | C33: ="GNPA "&TEXT('Business Performance Scorecard'!C192,"0.00%") -> GNPA 1.37% | D33: =IF('Business Performance Scorecard'!C192<0.013,"GREEN",IF('Business Performance Scorecard'!C192<0.02,"YELLOW","RED")) -> YELLOW | E33: =IF(D33="GREEN","Maintain",IF(D33="YELLOW","Improve","Immediate Focus")) -> Improve
B34: Treasury | C34: ="Cost of Borrowing "&TEXT('Business Performance Scorecard'!C200,"0.00%") -> Cost of Borrowing 7.72% | D34: =IF('Business Performance Scorecard'!C200<0.07,"GREEN",IF('Business Performance Scorecard'!C200<0.08,"YELLOW","RED")) -> YELLOW | E34: =IF(D34="GREEN","Maintain",IF(D34="YELLOW","Improve","Immediate Focus")) -> Improve
B35: Branch Productivity | C35: ="Avg. AUM/Branch ₹"&TEXT('Branch Profitability'!F7,"0.0")&" Cr" -> Avg. AUM/Branch ₹36.2 Cr | D35: =IF('Branch Profitability'!F7>'Branch Profitability'!E7*1.15,"GREEN",IF('Branch Profitability'!F7>'Branch Profitability'!E7,"YELLOW","RED")) -> GREEN | E35: =IF(D35="GREEN","Maintain",IF(D35="YELLOW","Improve","Immediate Focus")) -> Maintain
B36: Cost Efficiency | C36: ="Cost-to-Income "&TEXT('KPIs & Ratios'!H30*100,"0.0")&"%" -> Cost-to-Income 52.0% | D36: =IF('KPIs & Ratios'!H30*100<45,"GREEN",IF('KPIs & Ratios'!H30*100<55,"YELLOW","RED")) -> YELLOW | E36: =IF(D36="GREEN","Maintain",IF(D36="YELLOW","Improve","Immediate Focus")) -> Improve
B37: Digital Business | C37: ="DDP Share "&TEXT('KPIs & Ratios'!F76,"0.0%")&" (last disclosed FY24)" -> DDP Share 82.0% (last disclosed FY24) | D37: GREEN | E37: =IF(D37="GREEN","Accelerate",IF(D37="YELLOW","Improve","Immediate Focus")) -> Accelerate
B39: ="5. FORECAST OUTLOOK ("&'Scenario Analysis'!C5&" Case)" -> 5. FORECAST OUTLOOK (Base Case)
B40: Metric | C40: FY26A | D40: FY27E | E40: Direction | F40: Key Driver
B41: Total Income (₹ Cr) | C41: ='Profit & Loss'!H15 -> 6795.65 | D41: ='Profit & Loss'!I15 -> 11250.409 | E41: =IF(D41>C41,"▲","▼") -> ▲ | F41: Higher AUM
B42: PAT (₹ Cr) | C42: ='KPIs & Ratios'!H35 -> 541.81 | D42: ='KPIs & Ratios'!I35 -> 1781.8731 | E42: =IF(D42>C42,"▲","▼") -> ▲ | F42: Lower Credit Cost
B43: ROE % (Consolidated) | C43: ='KPIs & Ratios'!H34*100 -> 5.8501639 | D43: ='KPIs & Ratios'!I34*100 -> 12.977669 | E43: =IF(D43>C43,"▲","▼") -> ▲ | F43: Better Productivity
B44: Total Borrowings (₹ Cr) | C44: ='KPIs & Ratios'!H49 -> 48098.3 | D44: ='KPIs & Ratios'!I49 -> 73402.767 | E44: =IF(D44>C44,"▲","▼") -> ▲ | F44: Portfolio Growth
B46: 6. VALUE CREATION ENGINE (linked to Value Creation Tracker)
B47: Initiative | C47: KPI Impact | D47: Business Impact | E47: ₹ Cr p.a.
B48: ='Value Creation Tracker'!C7 -> Treasury diversification — higher NCD mix, longer tenor | C48: Cost of Funds ↓ | D48: NIM ↑ | E48: ='Value Creation Tracker'!G7 -> 120
B49: ='Value Creation Tracker'!C5 -> Branch productivity uplift (staggered gold-loan branch ramp-up) | C49: Cost-to-Income ↓ | D49: ROE ↑ | E49: ='Value Creation Tracker'!G5 -> 90
...

Sheet Business Performance Scorecard
B1: VISUAL KPI SUMMARY | J1: ⌂ Home
B2: Poonawalla Fincorp Limited | Actuals FY2024–FY2026 & Forecast FY2027E–FY2031E
B3: ="VISUAL KPI TRENDS — bars run newest at top: FY31E → FY24 (bottom). Teal = actuals FY24-26. Green = "&UPPER('Scenario Analysis'!C5)&" case forecast FY27E-31E." -> VISUAL KPI TRENDS — bars run newest at top: FY31E → FY24 (bottom). Teal = actuals FY24-26. Green = BASE case forecast FY27E-31E.
B4: Assets under Management | D4: Net Interest Income (NII) | F4: Gross NPA
B5: (₹ Crore, Consolidated basis for forecast) | D5: (₹ Crore) | F5: (%)
B15: ="AUM reached ₹"&TEXT('KPIs & Ratios'!H95,"#,##0")&" Cr in FY26 (+"&TEXT('KPIs & Ratios'!H8,"0.0%")&" YoY) and is projected to scale further under the driver-based forecast, reaching ~₹"&TEXT('KPIs & Ratios'!M95/100000,"0.00")&" lakh Cr by FY31E in the "&'Scenario Analysis'!C5&" Case." -> AUM reached ₹60,348 Cr in FY26 (+69.4% YoY) and is projected to scale further under the driver-based forecast, reaching ~₹2.46 lakh Cr by FY31E in the Base Case. | D15: NII rose to ₹4,029 Cr in FY26 from ₹2,708 Cr in FY25. The forecast (green bars) is driven by the Revenue Forecast tab's average-AUM × yield methodology. | F15: Gross NPA improved to 1.44% in FY26. The forecast glide path (Credit Cost Forecast tab) assumes continued underwriting discipline, easing further through FY31E.
B24: Net NPA | D24: Profit After Tax* | F24: Pre-Provision Operating Profit
B25: (%) | D25: (₹ Crore) | F25: (₹ Crore)
B35: Net NPA eased to 0.74% in FY26, moving in line with Gross NPA. Forecast years assume the PCR ratio holds broadly steady. | D35: ="PAT (excl. exceptional items) recovered to ₹"&TEXT('KPIs & Ratios'!H35,"#,##0")&" Cr in FY26. The "&'Scenario Analysis'!C5&" Case forecast projects PAT of ₹"&TEXT('KPIs & Ratios'!M35,"#,##0")&" Cr by FY31E as credit costs normalise and scale benefits compound." -> PAT (excl. exceptional items) recovered to ₹542 Cr in FY26. The Base Case forecast projects PAT of ₹7,832 Cr by FY31E as credit costs normalise and scale benefits compound. | F35: PPOP rose to ₹1,934 Cr in FY26. Forecast PPOP growth reflects NII scaling faster than the modelled opex build-out (Operating Cost Forecast tab).
B44: Cost of Borrowing | D44: Return on Assets (ROA)* | F44: Shareholders' Funds
B45: (%) | D45: (%) | F45: (₹ Crore)
B55: Cost of borrowing declined to 7.73% in FY26. The forecast (Funding Forecast tab) assumes gradual further easing as the funding mix diversifies. | D55: ="ROA improved to "&TEXT('KPIs & Ratios'!H33*100,"0.00")&"% in FY26. The "&'Scenario Analysis'!C5&" Case reaches "&TEXT('KPIs & Ratios'!K33*100,"0.0")&"% by FY29E — against management's stated 3.0-3.5% exit guidance (see KPIs & Ratios guidance cross-check)." -> ROA improved to 1.14% in FY26. The Base Case reaches 3.0% by FY29E — against management's stated 3.0-3.5% exit guidance (see KPIs & Ratios guidance cross-check). | F55: Shareholders' funds reached ₹10,298 Cr in FY26. Forecast growth (Balance Sheet tab) assumes retained earnings plus periodic capital raises to sustain the CRAR.
B64: Capital Adequacy Ratio (CRAR)
B65: (%, forecast is an approximation)
B75: CRAR moderated to 16.83% in FY26. True regulatory CRAR forecasting needs a risk-weighted-assets model beyond this workbook's scope, so FY27E-31E (green) uses the Equity/Assets % trend as a directional proxy, anchored to the FY26A level — not a substitute for a real capital calculation.
B84: CEO SUMMARY
B85: ="What happened? AUM grew "&TEXT('KPIs & Ratios'!H8,"0.0%")&" YoY to ₹"&TEXT('Business Performance Scorecard'!H161,"#,##0")&" Cr, with PAT of ₹"&TEXT('KPIs & Ratios'!H35,"#,##0")&" Cr in FY26, supported by strong secured lending momentum." -> What happened? AUM grew 69.4% YoY to ₹60,348 Cr, with PAT of ₹542 Cr in FY26, supported by strong secured lending momentum.
B86: ="Why? Disciplined underwriting held Gross NPA at "&TEXT('Business Performance Scorecard'!C192,"0.00%")&" (Q1 FY27), funding costs stayed manageable at "&TEXT('Business Performance Scorecard'!C200,"0.00%")&", and average earning assets scaled with the branch network." -> Why? Disciplined underwriting held Gross NPA at 1.37% (Q1 FY27), funding costs stayed manageable at 7.72%, and average earning assets scaled with the branch network.
B87: ="What next? Focus on funding cost optimisation, operating efficiency (Cost-to-Income at "&TEXT('KPIs & Ratios'!H30*100,"0.0")&"%), and branch productivity to sustain ROE expansion toward the FY27E Base Case of "&TEXT('KPIs & Ratios'!I34*100,"0.0")&"%." -> What next? Focus on funding cost optimisation, operating efficiency (Cost-to-Income at 52.0%), and branch productivity to sustain ROE expansion toward the FY27E Base Case of 13.0%.
B90: BUSINESS HEALTH
B91: Dimension | C91: KPI | D91: Actual | E91: Target (FY27E) | F91: YoY % | G91: Trend | H91: Status
B92: Growth | C92: AUM (₹ Cr) | D92: ='Business Performance Scorecard'!H161 -> 60348 | E92: ='Business Drivers'!D21 -> 86376.468 | F92: ='KPIs & Ratios'!H8 -> 0.69369369 | G92: =IF(F92>0,"▲","▼") -> ▲ | H92: =IF(F92>0.2,"GREEN",IF(F92>0.1,"YELLOW","RED")) -> GREEN
B93: Profitability | C93: ROA % | D93: ='Business Performance Scorecard'!C196*100 -> 1.98 | E93: ='KPIs & Ratios'!I33*100 -> 2.3208797 | F93: n/a | G93: =IF(E93>D93,"▲","▼") -> ▲ | H93: =IF(D93>2,"GREEN",IF(D93>1,"YELLOW","RED")) -> YELLOW
B94: Risk | C94: GNPA % | D94: ='Business Performance Scorecard'!C192 -> 0.0137 | E94: ='Credit Cost Forecast'!D6 -> 0.0135 | F94: n/a | G94: =IF(D94<0.0144,"▼","▲") -> ▼ | H94: =IF(D94<0.01,"GREEN",IF(D94<0.02,"YELLOW","RED")) -> YELLOW
B95: Efficiency | C95: Cost-to-Income % | D95: ='KPIs & Ratios'!H30*100 -> 52.009442 | E95: ='KPIs & Ratios'!I30*100 -> 41.033648 | F95: n/a | G95: =IF(E95<D95,"▲","▼") -> ▲ | H95: =IF(D95<45,"GREEN",IF(D95<55,"YELLOW","RED")) -> YELLOW
B96: Liquidity | C96: LCR % | D96: ='KPIs & Ratios'!H54 -> 181 | E96: >150% target | F96: n/a | G96: → | H96: =IF(D96>150,"GREEN",IF(D96>120,"YELLOW","RED")) -> GREEN
B97: Shareholder | C97: ROE % (Consolidated) | D97: ='KPIs & Ratios'!H34*100 -> 5.8501639 | E97: ='KPIs & Ratios'!I34*100 -> 12.977669 | F97: n/a | G97: =IF(E97>D97,"▲","▼") -> ▲ | H97: =IF(D97>15,"GREEN",IF(D97>8,"YELLOW","RED")) -> RED
B99: EXECUTIVE NARRATIVE
B100: ="Business Performance: Growth remained strong, driven by secured lending expansion (AUM +"&TEXT('KPIs & Ratios'!H8,"0.0%")&" YoY to ₹"&TEXT('Business Performance Scorecard'!H161,"#,##0")&" Cr), while asset quality was broadly maintained (GNPA "&TEXT('Business Performance Scorecard'!C192,"0.00%")&", Q1 FY27)." -> Business Performance: Growth remained strong, driven by secured lending expansion (AUM +69.4% YoY to ₹60,348 Cr), while asset quality was broadly maintained (GNPA 1.37%, Q1 FY27).
B103: ="Profitability: PAT reached ₹"&TEXT('KPIs & Ratios'!H35,"#,##0")&" Cr in FY26, aided by higher NII and stable funding costs ("&TEXT('Business Performance Scorecard'!C200,"0.00%")&"). The primary management focus is now improving operating efficiency (Cost-to-Income "&TEXT('KPIs & Ratios'!H30*100,"0.0")&"%) without compromising the growth trajectory." -> Profitability: PAT reached ₹542 Cr in FY26, aided by higher NII and stable funding costs (7.72%). The primary management focus is now improving operating efficiency (Cost-to-Income 52.0%) without compromising the growth trajectory.
B106: ="Outlook: The Base Case forecast projects PAT scaling to ₹"&TEXT('KPIs & Ratios'!I35,"#,##0")&" Cr by FY27E as credit costs normalise and branch productivity improves — with ₹"&TEXT('Value Creation Tracker'!G10,"#,##0")&" Cr of identified value-creation impact already quantified across five initiatives (see Value Creation section below)." -> Outlook: The Base Case forecast projects PAT scaling to ₹1,782 Cr by FY27E as credit costs normalise and branch productivity improves — with ₹350 Cr of identified value-creation impact already quantified across five initiatives (see Value Creation section below).
B110: VALUE DRIVER ENGINE
B111: Customers → Disbursement → AUM → Yield → NII → PAT → ROE → Shareholder Value
D112: Driver | E112: Status | F112: Impact
D113: Customer Growth | E113: =IF('Business Drivers'!C9>'Customer Analytics'!G5,"GREEN","YELLOW") -> GREEN | F113: High
D114: Yield | E114: =IF('KPIs & Ratios'!H25>'KPIs & Ratios'!G25,"GREEN","YELLOW") -> YELLOW | F114: High
D115: Credit Cost | E115: =IF('KPIs & Ratios'!H43<'KPIs & Ratios'!G43,"GREEN","YELLOW") -> GREEN | F115: High
D116: Operating Cost | E116: =IF('KPIs & Ratios'!H30<'KPIs & Ratios'!G30,"GREEN","YELLOW") -> YELLOW | F116: Medium
D117: Cost of Funds | E117: =IF('KPIs & Ratios'!H26<'KPIs & Ratios'!G26,"GREEN","YELLOW") -> YELLOW | F117: Medium
B119: CEO DECISION BOX
...

Sheet Business Drivers
B1: POONAWALLA FINCORP LIMITED — Business Drivers (Customers → Loan Size → Disbursement → AUM) | L1: ⌂ Home
B2: This is the core driver chain. AUM is DERIVED from Customers, Avg Loan Size, Cross-sell and Portfolio Runoff — it is not assumed directly. Branches and Employees are forecast separately and feed the Operating Cost Forecast sheet.
B4: Particulars | C4: FY2026A | D4: FY2027E | E4: FY2028E | F4: FY2029E | G4: FY2030E | H4: FY2031E | I4: Rationale / Source
B6: 1. CUSTOMER & DISBURSEMENT DRIVERS
B7: New Customers Added (Lakh) — Base Case (scenario multiplier applied below) | D7: 7 | E7: 8 | F7: 8.5 | G7: 9 | H7: 9.5 | I7: Illustrative acquisition pace, scaled to branch expansion (row 25) and the Company's disclosed multi-product distribution build-out. FY2026A base: "over twenty two lakh customers" (AR FY2026 pg.35).
B8: Cross-sell Penetration Rate % (of prior cumulative customers) | C8: 0.27 | D8: 0.28 | E8: 0.3 | F8: 0.32 | G8: 0.33 | H8: 0.34 | I8: Linked from Customer Analytics tab (illustrative FY2026 rate 27%); gradual improvement assumed, consistent with the Company's stated "cross-sell to high-value cohorts at low acquisition cost" strategy (AR FY2025 pg.4).
B9: Cumulative Customers (Lakh) — scenario-adjusted | C9: 22 | D9: =C9+D7*'Scenario Analysis'!$C$16 -> 29 | E9: =D9+E7*'Scenario Analysis'!$C$16 -> 37 | F9: =E9+F7*'Scenario Analysis'!$C$16 -> 45.5 | G9: =F9+G7*'Scenario Analysis'!$C$16 -> 54.5 | H9: =G9+H7*'Scenario Analysis'!$C$16 -> 64 | I9: FY2026A: "over twenty two lakh customers as of March 31, 2026" (AR FY2026 pg.35).
B10: Average Loan Size (₹ Lakh) | D10: 3.8 | E10: 3.95 | F10: 4.1 | G10: 4.25 | H10: 4.4 | I10: Illustrative blended ticket size across the secured (LAP ~₹3-8L, Gold Loan smaller) and unsecured (Personal/Business Loan ~₹1-3L) mix, rising gradually with ticket-size inflation. Individual product ticket ranges disclosed in AR FY2026 pg.60-61.
B12: Disbursement to New Customers (₹ Cr) — scenario-adjusted | D12: =D7*'Scenario Analysis'!$C$16*D10*1000 -> 26600 | E12: =E7*'Scenario Analysis'!$C$16*E10*1000 -> 31600 | F12: =F7*'Scenario Analysis'!$C$16*F10*1000 -> 34850 | G12: =G7*'Scenario Analysis'!$C$16*G10*1000 -> 38250 | H12: =H7*'Scenario Analysis'!$C$16*H10*1000 -> 41800
B13: Disbursement to Existing Customers / Cross-sell (₹ Cr) | D13: =C9*D8*D10*1000 -> 23408 | E13: =D9*E8*E10*1000 -> 34365 | F13: =E9*F8*F10*1000 -> 48544 | G13: =F9*G8*G10*1000 -> 63813.75 | H13: =G9*H8*H10*1000 -> 81532
B14: Total Disbursement (₹ Cr) | D14: =D12+D13 -> 50008 | E14: =E12+E13 -> 65965 | F14: =F12+F13 -> 83394 | G14: =G12+G13 -> 102063.75 | H14: =H12+H13 -> 123332
B16: 2. LOAN BOOK ROLL-FORWARD (AUM is DERIVED here, not assumed)
B17: Portfolio Runoff Rate % (repayments/amortisation, % of opening AUM) | D17: 0.35 | E17: 0.35 | F17: 0.35 | G17: 0.35 | H17: 0.35 | I17: Illustrative assumption for a mixed-tenure retail/MSME book (loan tenures typically range 6-72 months per AR FY2026 pg.60-61); ~35% straight-line runoff approximates a blended average tenure of ~3 years. Held flat as the mix is assumed broadly stable.
B18: Opening AUM (₹ Cr) | D18: =C21 -> 55951.49 | E18: =D21 -> 86376.468 | F18: =E21 -> 122109.7 | G18: =F21 -> 162765.31 | H18: =G21 -> 207861.2
B19: (+) Disbursements (₹ Cr) | D19: =D14 -> 50008 | E19: =E14 -> 65965 | F19: =F14 -> 83394 | G19: =G14 -> 102063.75 | H19: =H14 -> 123332
B20: (−) Repayments / Runoff (₹ Cr) | D20: =-D18*D17 -> -19583.021 | E20: =-E18*E17 -> -30231.764 | F20: =-F18*F17 -> -42738.397 | G20: =-G18*G17 -> -56967.858 | H20: =-H18*H17 -> -72751.42
B21: Closing AUM / Loan Book (₹ Cr) | C21: ='Balance Sheet'!H14 -> 55951.49 | D21: =D18+D19+D20 -> 86376.468 | E21: =E18+E19+E20 -> 122109.7 | F21: =F18+F19+F20 -> 162765.31 | G21: =G18+G19+G20 -> 207861.2 | H21: =H18+H19+H20 -> 258441.78
B22: AUM Growth % YoY | D22: =IFERROR(D21/C21-1,"") -> 0.54377423 | E22: =IFERROR(E21/D21-1,"") -> 0.41369179 | F22: =IFERROR(F21/E21-1,"") -> 0.33294326 | G22: =IFERROR(G21/F21-1,"") -> 0.27706084 | H22: =IFERROR(H21/G21-1,"") -> 0.24333825
B23: (Memo) AUM as multiple of FY2025A base (₹35,631 Cr) | D23: =IFERROR(D21/35631,"") -> 2.4241943 | E23: =IFERROR(E21/35631,"") -> 3.4270636 | F23: =IFERROR(F21/35631,"") -> 4.5680814 | G23: =IFERROR(G21/35631,"") -> 5.8337178 | H23: =IFERROR(H21/35631,"") -> 7.2532845 | I23: Cross-check vs management's disclosed guidance of "5-6x AUM growth over the next 5 years (FY25 onwards)" (AR FY2026 pg.2-3). FY2030E (5 years from FY25) shows here.
B25: 3. BRANCH & EMPLOYEE DRIVERS
B26: Net Branch Additions (count, linked from Assumptions) | D26: =Assumptions!D13 -> 150 | E26: =Assumptions!E13 -> 130 | F26: =Assumptions!F13 -> 100 | G26: =Assumptions!G13 -> 90 | H26: =Assumptions!H13 -> 80
B27: Branch Count (cumulative) | C27: 500 | D27: =C27+D26 -> 650 | E27: =D27+E26 -> 780 | F27: =E27+F26 -> 880 | G27: =F27+G26 -> 970 | H27: =G27+H26 -> 1050 | I27: FY2026A: "500+ branches (including 400 gold loan branches)" (AR FY2026 pg.2).
B28: Employees per Branch (linked from Assumptions) | C28: =Assumptions!C14 -> 11.72 | D28: =Assumptions!D14 -> 11.5 | E28: =Assumptions!E14 -> 11.2 | F28: =Assumptions!F14 -> 11 | G28: =Assumptions!G14 -> 10.8 | H28: =Assumptions!H14 -> 10.6
B29: Employees (count) | C29: 5860 | D29: =ROUND(D27*D28,0) -> 7475 | E29: =ROUND(E27*E28,0) -> 8736 | F29: =ROUND(F27*F28,0) -> 9680 | G29: =ROUND(G27*G28,0) -> 10476 | H29: =ROUND(H27*H28,0) -> 11130 | I29: FY2026A: "5,860 Employees" (AR FY2026 pg.4). Forecast = Branch Count × Employees per Branch ratio (row 28).
B30: Average AUM per Branch (₹ Cr) | C30: =IFERROR(C21/C27,"") -> 111.90298 | D30: =IFERROR(AVERAGE(C21,D21)/AVERAGE(C27,D27),"") -> 123.76344 | E30: =IFERROR(AVERAGE(D21,E21)/AVERAGE(D27,E27),"") -> 145.79453 | F30: =IFERROR(AVERAGE(E21,F21)/AVERAGE(E27,F27),"") -> 171.61145 | G30: =IFERROR(AVERAGE(F21,G21)/AVERAGE(F27,G27),"") -> 200.33865 | H30: =IFERROR(AVERAGE(G21,H21)/AVERAGE(G27,H27),"") -> 230.84306

Sheet KPIs & Ratios
B1: POONAWALLA FINCORP LIMITED — NBFC KPIs & Financial Ratios (Consolidated) | O1: ⌂ Home
B2: All ratios below are LIVE FORMULAS linked to the Balance Sheet, Profit & Loss, and Treasury sheets (FY2021-FY2026A) and to the integrated forecast sheets — Business Drivers, Funding/Credit Cost Forecast — for FY2027E-FY2031E. Ratios requiring an opening balance (Average-based) start from FY2022. Rows that depend on tabs without a forecast extension (Customer Analytics, Branch/Product Profitability, Treasury, Executive Dashboard's disclosed-only metrics) are left blank for FY2027E-FY2031E with a note, rather than estimated.
B4: Particulars | C4: FY2021 | D4: FY2022 | E4: FY2023 | F4: FY2024 | G4: FY2025 | H4: FY2026 | I4: FY2027E | J4: FY2028E | K4: FY2029E | L4: FY2030E | M4: FY2031E
B6: GROWTH METRICS (YoY %)
B7: Total Assets Growth % | D7: =IFERROR('Balance Sheet'!D31/'Balance Sheet'!C31-1,"") -> 0.24451057 | E7: =IFERROR('Balance Sheet'!E31/'Balance Sheet'!D31-1,"") -> 0.41221388 | F7: =IFERROR('Balance Sheet'!F31/'Balance Sheet'!E31-1,"") -> 0.037306944 | G7: =IFERROR('Balance Sheet'!G31/'Balance Sheet'!F31-1,"") -> 0.454315 | H7: =IFERROR('Balance Sheet'!H31/'Balance Sheet'!G31-1,"") -> 0.72057274 | I7: =IFERROR('Balance Sheet'!I31/'Balance Sheet'!H31-1,"") -> 0.54766136 | J7: =IFERROR('Balance Sheet'!J31/'Balance Sheet'!I31-1,"") -> 0.39662582 | K7: =IFERROR('Balance Sheet'!K31/'Balance Sheet'!J31-1,"") -> 0.32172306 | ... M7: =IFERROR('Balance Sheet'!M31/'Balance Sheet'!L31-1,"") -> 0.23633683
B8: Loans / AUM Growth % (Reported, Standalone — linked from Executive Dashboard) | E8: ='Business Performance Scorecard'!E162 -> 0.3721207 | F8: ='Business Performance Scorecard'!F162 -> 0.5488447 | G8: ='Business Performance Scorecard'!G162 -> 0.42506899 | H8: ='Business Performance Scorecard'!H162 -> 0.69369369 | I8: ='Business Drivers'!D22 -> 0.54377423 | J8: ='Business Drivers'!E22 -> 0.41369179 | K8: ='Business Drivers'!F22 -> 0.33294326 | L8: ='Business Drivers'!G22 -> 0.27706084 | M8: ='Business Drivers'!H22 -> 0.24333825
B9: Total Income Growth % | D9: =IFERROR('Profit & Loss'!D15/'Profit & Loss'!C15-1,"") -> -0.13239153 | E9: =IFERROR('Profit & Loss'!E15/'Profit & Loss'!D15-1,"") -> -0.016045531 | F9: =IFERROR('Profit & Loss'!F15/'Profit & Loss'!E15-1,"") -> 0.56717689 | G9: =IFERROR('Profit & Loss'!G15/'Profit & Loss'!F15-1,"") -> 0.3417214 | H9: =IFERROR('Profit & Loss'!H15/'Profit & Loss'!G15-1,"") -> 0.60926059 | I9: =IFERROR('Profit & Loss'!I15/'Profit & Loss'!H15-1,"") -> 0.65553092 | J9: =IFERROR('Profit & Loss'!J15/'Profit & Loss'!I15-1,"") -> 0.4180989 | K9: =IFERROR('Profit & Loss'!K15/'Profit & Loss'!J15-1,"") -> 0.31711665 | ... M9: =IFERROR('Profit & Loss'!M15/'Profit & Loss'!L15-1,"") -> 0.23602943
B10: PAT Growth % | D10: =IFERROR('Profit & Loss'!D38/'Profit & Loss'!C38-1,"") -> -1.671617 | E10: =IFERROR('Profit & Loss'!E38/'Profit & Loss'!D38-1,"") -> 0.8247516 | F10: =IFERROR('Profit & Loss'!F38/'Profit & Loss'!E38-1,"") -> 1.4569143 | G10: =IFERROR('Profit & Loss'!G38/'Profit & Loss'!F38-1,"") -> -1.0584293 | H10: =IFERROR('Profit & Loss'!H38/'Profit & Loss'!G38-1,"") -> -6.5095587 | I10: =IFERROR('Profit & Loss'!I38/'Profit & Loss'!H38-1,"") -> 2.2887415 | J10: =IFERROR('Profit & Loss'!J38/'Profit & Loss'!I38-1,"") -> 0.74956607 | K10: =IFERROR('Profit & Loss'!K38/'Profit & Loss'!J38-1,"") -> 0.44824919 | ... M10: =IFERROR('Profit & Loss'!M38/'Profit & Loss'!L38-1,"") -> 0.31864324
B11: Net Worth (Total Equity) Growth % | D11: =IFERROR('Balance Sheet'!D55/'Balance Sheet'!C55-1,"") -> 1.7608842 | E11: =IFERROR('Balance Sheet'!E55/'Balance Sheet'!D55-1,"") -> 0.13451964 | F11: =IFERROR('Balance Sheet'!F55/'Balance Sheet'!E55-1,"") -> 0.1882552 | G11: =IFERROR('Balance Sheet'!G55/'Balance Sheet'!F55-1,"") -> 0.00092811629 | H11: =IFERROR('Balance Sheet'!H55/'Balance Sheet'!G55-1,"") -> 0.2658924 | I11: =IFERROR('Balance Sheet'!I55/'Balance Sheet'!H55-1,"") -> 0.65364962 | J11: =IFERROR('Balance Sheet'!J55/'Balance Sheet'!I55-1,"") -> 0.4324948 | K11: =IFERROR('Balance Sheet'!K55/'Balance Sheet'!J55-1,"") -> 0.33728963 | ... M11: =IFERROR('Balance Sheet'!M55/'Balance Sheet'!L55-1,"") -> 0.24009603
B12: Disbursements (₹ Cr, company-disclosed) | C12: 3680.21 | D12: 7524 | E12: 15751 | F12: 33289 | I12: ='Business Drivers'!D14 -> 50008 | J12: ='Business Drivers'!E14 -> 65965 | K12: ='Business Drivers'!F14 -> 83394 | L12: ='Business Drivers'!G14 -> 102063.75 | M12: ='Business Drivers'!H14 -> 123332
B13: Disbursement Growth % | D13: =IFERROR(D12/C12-1,"") -> 1.0444486 | E13: =IFERROR(E12/D12-1,"") -> 1.0934343 | F13: =IFERROR(F12/E12-1,"") -> 1.1134531 | I13: =IFERROR(I12/H12-1,"") | J13: =IFERROR(J12/I12-1,"") -> 0.31908895 | K13: =IFERROR(K12/J12-1,"") -> 0.26421587 | L13: =IFERROR(L12/K12-1,"") -> 0.22387402 | M13: =IFERROR(M12/L12-1,"") -> 0.20838202
B14: Customer Base (Lakh, linked from Customer Analytics tab) | E14: ='Customer Analytics'!C5 -> 11 | F14: ='Customer Analytics'!D5 -> 15 | G14: ='Customer Analytics'!E5 -> 18 | H14: ='Customer Analytics'!F5 -> 22 | I14: ='Business Drivers'!D9 -> 29 | J14: ='Business Drivers'!E9 -> 37 | K14: ='Business Drivers'!F9 -> 45.5 | L14: ='Business Drivers'!G9 -> 54.5 | M14: ='Business Drivers'!H9 -> 64
B15: Customer Growth % | F15: =IFERROR(F14/E14-1,"") -> 0.36363636 | G15: =IFERROR(G14/F14-1,"") -> 0.2 | H15: =IFERROR(H14/G14-1,"") -> 0.22222222 | I15: =IFERROR(I14/H14-1,"") -> 0.31818182 | J15: =IFERROR(J14/I14-1,"") -> 0.27586207 | K15: =IFERROR(K14/J14-1,"") -> 0.22972973 | L15: =IFERROR(L14/K14-1,"") -> 0.1978022 | M15: =IFERROR(M14/L14-1,"") -> 0.17431193
B16: Market Share % — not numerically disclosed by the Company (only qualitative “gaining market share each year”, AR FY2025 pg.4); left blank rather than estimated
B17: Number of Loan Products (count, company-disclosed) | H17: 13
B18: Cross-sell / Repeat Rate % (illustrative — linked from Customer Analytics tab) | E18: ='Customer Analytics'!C8 -> 0.18 | F18: ='Customer Analytics'!D8 -> 0.21 | G18: ='Customer Analytics'!E8 -> 0.24 | H18: ='Customer Analytics'!F8 -> 0.27
B20: PROFITABILITY RATIOS
B21: Net Interest Income – NII (₹ Cr) [Interest Income − Finance Costs] | C21: ='Profit & Loss'!C8-'Profit & Loss'!C17 -> 1065.2235 | D21: ='Profit & Loss'!D8-'Profit & Loss'!D17 -> 1194.3176 | E21: ='Profit & Loss'!E8-'Profit & Loss'!E17 -> 1219.91 | F21: ='Profit & Loss'!F8-'Profit & Loss'!F17 -> 1949.26 | G21: ='Profit & Loss'!G8-'Profit & Loss'!G17 -> 2359.41 | H21: ='Profit & Loss'!H8-'Profit & Loss'!H17 -> 3374.14 | I21: ='Profit & Loss'!I8-'Profit & Loss'!I17 -> 5761.7377 | J21: ='Profit & Loss'!J8-'Profit & Loss'!J17 -> 8195.5298 | ... M21: ='Profit & Loss'!M8-'Profit & Loss'!M17 -> 16306.535
B22: Average Total Assets (₹ Cr) | D22: =AVERAGE('Balance Sheet'!C31,'Balance Sheet'!D31) -> 14827.442 | E22: =AVERAGE('Balance Sheet'!D31,'Balance Sheet'!E31) -> 19831.655 | F22: =AVERAGE('Balance Sheet'!E31,'Balance Sheet'!F31) -> 23653.755 | G22: =AVERAGE('Balance Sheet'!F31,'Balance Sheet'!G31) -> 29558.42 | H22: =AVERAGE('Balance Sheet'!G31,'Balance Sheet'!H31) -> 47650.75 | I22: =AVERAGE('Balance Sheet'!H31,'Balance Sheet'!I31) -> 76775.762 | J22: =AVERAGE('Balance Sheet'!I31,'Balance Sheet'!J31) -> 111778.59 | K22: =AVERAGE('Balance Sheet'!J31,'Balance Sheet'!K31) -> 151233.8 | ... M22: =AVERAGE('Balance Sheet'!L31,'Balance Sheet'!M31) -> 244179.95
B23: Net Interest Margin – NIM % (NII ÷ Avg. Total Assets) | D23: =IFERROR(D21/D22,"") -> 0.080547787 | E23: =IFERROR(E21/E22,"") -> 0.061513272 | F23: =IFERROR(F21/F22,"") -> 0.082408057 | G23: =IFERROR(G21/G22,"") -> 0.079821926 | H23: =IFERROR(H21/H22,"") -> 0.070809798 | I23: =IFERROR(I21/I22,"") -> 0.07504631 | J23: =IFERROR(J21/J22,"") -> 0.07331932 | K23: =IFERROR(K21/K22,"") -> 0.070923355 | ... M23: =IFERROR(M21/M22,"") -> 0.066780811
B24: Average Loans (₹ Cr) | D24: =AVERAGE('Balance Sheet'!C14,'Balance Sheet'!D14) -> 13105.963 | E24: =AVERAGE('Balance Sheet'!D14,'Balance Sheet'!E14) -> 15034.614 | F24: =AVERAGE('Balance Sheet'!E14,'Balance Sheet'!F14) -> 18632.47 | G24: =AVERAGE('Balance Sheet'!F14,'Balance Sheet'!G14) -> 27370.685 | H24: =AVERAGE('Balance Sheet'!G14,'Balance Sheet'!H14) -> 44323.225 | I24: =AVERAGE('Balance Sheet'!H14,'Balance Sheet'!I14) -> 70381.175 | J24: =AVERAGE('Balance Sheet'!I14,'Balance Sheet'!J14) -> 101687.17 | K24: =AVERAGE('Balance Sheet'!J14,'Balance Sheet'!K14) -> 137680.56 | ... M24: =AVERAGE('Balance Sheet'!L14,'Balance Sheet'!M14) -> 222470.18
B25: Yield on Advances % (Interest Income ÷ Avg. Loans) | D25: =IFERROR('Profit & Loss'!D8/D24,"") -> 0.14577237 | E25: =IFERROR('Profit & Loss'!E8/E24,"") -> 0.12073406 | F25: =IFERROR('Profit & Loss'!F8/F24,"") -> 0.15561866 | G25: =IFERROR('Profit & Loss'!G8/G24,"") -> 0.14155656 | H25: =IFERROR('Profit & Loss'!H8/H24,"") -> 0.1385461 | I25: =IFERROR('Profit & Loss'!I8/I24,"") -> 0.14661274 | J25: =IFERROR('Profit & Loss'!J8/J24,"") -> 0.14351891 | K25: =IFERROR('Profit & Loss'!K8/K24,"") -> 0.13966433 | ... M25: =IFERROR('Profit & Loss'!M8/M24,"") -> 0.13309757
B26: Cost of Funds % (Finance Costs ÷ Avg. Borrowings, linked from Treasury) | D26: =IFERROR(Treasury!D19/100,"") -> 0.070413329 | E26: =IFERROR(Treasury!E19/100,"") -> 0.056616741 | F26: =IFERROR(Treasury!F19/100,"") -> 0.072542788 | G26: =IFERROR(Treasury!G19/100,"") -> 0.073977776 | H26: =IFERROR(Treasury!H19/100,"") -> 0.074796242 | I26: ='Funding Forecast'!D10 -> 0.075 | J26: ='Funding Forecast'!E10 -> 0.073 | K26: ='Funding Forecast'!F10 -> 0.072 | L26: ='Funding Forecast'!G10 -> 0.071 | M26: ='Funding Forecast'!H10 -> 0.07
B27: Interest Spread % (Yield − Cost of Funds) | D27: =IFERROR(D25-D26,"") -> 0.075359036 | E27: =IFERROR(E25-E26,"") -> 0.064117317 | F27: =IFERROR(F25-F26,"") -> 0.083075872 | G27: =IFERROR(G25-G26,"") -> 0.067578784 | H27: =IFERROR(H25-H26,"") -> 0.063749858 | I27: =IFERROR(I25-I26,"") -> 0.07161274 | J27: =IFERROR(J25-J26,"") -> 0.070518914 | K27: =IFERROR(K25-K26,"") -> 0.06766433 | ... M27: =IFERROR(M25-M26,"") -> 0.063097566
B28: Operating Expenses (₹ Cr) [Employee costs + D&A + Other expenses] | C28: ='Profit & Loss'!C21+'Profit & Loss'!C22+'Profit & Loss'!C23 -> 558.2843 | D28: ='Profit & Loss'!D21+'Profit & Loss'!D22+'Profit & Loss'!D23 -> 751.6504 | E28: ='Profit & Loss'!E21+'Profit & Loss'!E22+'Profit & Loss'!E23 -> 803.05 | F28: ='Profit & Loss'!F21+'Profit & Loss'!F22+'Profit & Loss'!F23 -> 807.36 | G28: ='Profit & Loss'!G21+'Profit & Loss'!G22+'Profit & Loss'!G23 -> 1276.85 | H28: ='Profit & Loss'!H21+'Profit & Loss'!H22+'Profit & Loss'!H23 -> 2095.45 | I28: ='Profit & Loss'!I21+'Profit & Loss'!I22+'Profit & Loss'!I23 -> 2746.5337 | J28: ='Profit & Loss'!J21+'Profit & Loss'!J22+'Profit & Loss'!J23 -> 3408.9553 | ... M28: ='Profit & Loss'!M21+'Profit & Loss'!M22+'Profit & Loss'!M23 -> 5376.0881
B29: Net Total Income (₹ Cr) [Total Income − Finance Costs] | C29: ='Profit & Loss'!C15-'Profit & Loss'!C17 -> 1252.0235 | D29: ='Profit & Loss'!D15-'Profit & Loss'!D17 -> 1324.8597 | E29: ='Profit & Loss'!E15-'Profit & Loss'!E17 -> 1413 | F29: ='Profit & Loss'!F15-'Profit & Loss'!F17 -> 2197.03 | G29: ='Profit & Loss'!G15-'Profit & Loss'!G17 -> 2707.75 | H29: ='Profit & Loss'!H15-'Profit & Loss'!H17 -> 4028.98 | I29: ='Profit & Loss'!I15-'Profit & Loss'!I17 -> 6693.3694 | J29: ='Profit & Loss'!J15-'Profit & Loss'!J17 -> 9555.6899 | ... M29: ='Profit & Loss'!M15-'Profit & Loss'!M17 -> 19340.005
B30: Cost-to-Income Ratio % (Opex ÷ Net Total Income) | C30: =IFERROR(C28/C29,"") -> 0.44590561 | D30: =IFERROR(D28/D29,"") -> 0.56734339 | E30: =IFERROR(E28/E29,"") -> 0.56832979 | F30: =IFERROR(F28/F29,"") -> 0.36747791 | G30: =IFERROR(G28/G29,"") -> 0.47155387 | H30: =IFERROR(H28/H29,"") -> 0.52009442 | I30: =IFERROR(I28/I29,"") -> 0.41033648 | J30: =IFERROR(J28/J29,"") -> 0.35674611 | ... M30: =IFERROR(M28/M29,"") -> 0.2779776
B31: Pre-Provisioning Operating Profit – PPOP (₹ Cr) [Net Total Income − Opex] | C31: =C29-C28 -> 693.7392 | D31: =D29-D28 -> 573.2093 | E31: =E29-E28 -> 609.95 | F31: =F29-F28 -> 1389.67 | G31: =G29-G28 -> 1430.9 | H31: =H29-H28 -> 1933.53 | I31: =I29-I28 -> 3946.8357 | J31: =J29-J28 -> 6146.7347 | ... M31: =M29-M28 -> 13963.917
B32: Average Total Equity (₹ Cr) | D32: =AVERAGE('Balance Sheet'!C55,'Balance Sheet'!D55) -> 4126.2624 | E32: =AVERAGE('Balance Sheet'!D55,'Balance Sheet'!E55) -> 6465.6952 | F32: =AVERAGE('Balance Sheet'!E55,'Balance Sheet'!F55) -> 7520.125 | G32: =AVERAGE('Balance Sheet'!F55,'Balance Sheet'!G55) -> 8170.87 | H32: =AVERAGE('Balance Sheet'!G55,'Balance Sheet'!H55) -> 9261.45 | I32: =AVERAGE('Balance Sheet'!H55,'Balance Sheet'!I55) -> 13730.302 | J32: =AVERAGE('Balance Sheet'!I55,'Balance Sheet'!J55) -> 20812.867 | K32: =AVERAGE('Balance Sheet'!J55,'Balance Sheet'!K55) -> 28647.424 | ... M32: =AVERAGE('Balance Sheet'!L55,'Balance Sheet'!M55) -> 46874.511
B33: Return on Assets – ROA % (PAT ÷ Avg. Total Assets) | D33: =IFERROR('Profit & Loss'!D38/D22,"") -> 0.025318596 | E33: =IFERROR('Profit & Loss'!E38/E22,"") -> 0.03454225 | F33: =IFERROR('Profit & Loss'!F38/F22,"") -> 0.07115403 | G33: =IFERROR('Profit & Loss'!G38/G22,"") -> -0.0033269708 | H33: =IFERROR('Profit & Loss'!H38/H22,"") -> 0.01137044 | I33: =IFERROR('Profit & Loss'!I38/I22,"") -> 0.023208797 | J33: =IFERROR('Profit & Loss'!J38/J22,"") -> 0.027889999 | K33: =IFERROR('Profit & Loss'!K38/K22,"") -> 0.029853932 | ... M33: =IFERROR('Profit & Loss'!M38/M22,"") -> 0.032075483
B34: Return on Equity – ROE % (PAT ÷ Avg. Total Equity) | D34: =IFERROR('Profit & Loss'!D38/D32,"") -> 0.090980641 | E34: =IFERROR('Profit & Loss'!E38/E32,"") -> 0.10594839 | F34: =IFERROR('Profit & Loss'!F38/F32,"") -> 0.22380745 | G34: =IFERROR('Profit & Loss'!G38/G32,"") -> -0.012035438 | H34: =IFERROR('Profit & Loss'!H38/H32,"") -> 0.058501639 | I34: =IFERROR('Profit & Loss'!I38/I32,"") -> 0.12977669 | J34: =IFERROR('Profit & Loss'!J38/J32,"") -> 0.14978737 | K34: =IFERROR('Profit & Loss'!K38/K32,"") -> 0.15760313 | ... M34: =IFERROR('Profit & Loss'!M38/M32,"") -> 0.16708846
B35: Profit After Tax – PAT (₹ Cr, linked from Profit & Loss) | C35: ='Profit & Loss'!C38 -> -558.9644 | D35: ='Profit & Loss'!D38 -> 375.41 | E35: ='Profit & Loss'!E38 -> 685.03 | F35: ='Profit & Loss'!F38 -> 1683.06 | G35: ='Profit & Loss'!G38 -> -98.34 | H35: ='Profit & Loss'!H38 -> 541.81 | I35: ='Profit & Loss'!I38 -> 1781.8731 | J35: ='Profit & Loss'!J38 -> 3117.5046 | ... M35: ='Profit & Loss'!M38 -> 7832.1898
B36: Fee & Commission Income (₹ Cr, linked from Profit & Loss) | C36: ='Profit & Loss'!C10 -> 71.6572 | D36: ='Profit & Loss'!D10 -> 63.917 | E36: ='Profit & Loss'!E10 -> 61.54 | F36: ='Profit & Loss'!F10 -> 73.22 | G36: ='Profit & Loss'!G10 -> 192.26 | H36: ='Profit & Loss'!H10 -> 419.75 | I36: ='Profit & Loss'!I10 -> 533.72984 | J36: ='Profit & Loss'!J10 -> 781.82315 | ... M36: ='Profit & Loss'!M10 -> 1981.7877
B37: Fee Income % of Total Income | C37: =IFERROR(C36/'Profit & Loss'!C15,"") -> 0.030460313 | D37: =IFERROR(D36/'Profit & Loss'!D15,"") -> 0.03131606 | E37: =IFERROR(E36/'Profit & Loss'!E15,"") -> 0.030643137 | F37: =IFERROR(F36/'Profit & Loss'!F15,"") -> 0.023264164 | G37: =IFERROR(G36/'Profit & Loss'!G15,"") -> 0.045528602 | H37: =IFERROR(H36/'Profit & Loss'!H15,"") -> 0.061767454 | I37: =IFERROR(I36/'Profit & Loss'!I15,"") -> 0.047440929 | J37: =IFERROR(J36/'Profit & Loss'!J15,"") -> 0.049004245 | ... M37: =IFERROR(M36/'Profit & Loss'!M15,"") -> 0.060709636
B38: Secured Lending Mix % (on-book AUM, company-disclosed) | F38: 0.49 | G38: 0.57 | H38: 0.54 | I38: 0.52 | J38: 0.51 | K38: 0.505 | L38: 0.5 | M38: 0.5
B39: Unsecured Lending Mix % | F39: =IFERROR(1-F38,"") -> 0.51 | G39: =IFERROR(1-G38,"") -> 0.43 | H39: =IFERROR(1-H38,"") -> 0.46 | I39: =IFERROR(1-I38,"") -> 0.48 | J39: =IFERROR(1-J38,"") -> 0.49 | K39: =IFERROR(1-K38,"") -> 0.495 | L39: =IFERROR(1-L38,"") -> 0.5 | M39: =IFERROR(1-M38,"") -> 0.5
B40: Operating Leverage (ppt) = Total Income Growth % − Opex Growth % | D40: =IFERROR(D9-(D28/C28-1),"") -> -0.47874929 | E40: =IFERROR(E9-(E28/D28-1),"") -> -0.084427853 | F40: =IFERROR(F9-(F28/E28-1),"") -> 0.56180985 | G40: =IFERROR(G9-(G28/F28-1),"") -> -0.23979119 | H40: =IFERROR(H9-(H28/G28-1),"") -> -0.031848387 | I40: =IFERROR(I9-(I28/H28-1),"") -> 0.34481787 | J40: =IFERROR(J9-(J28/I28-1),"") -> 0.17691431 | K40: =IFERROR(K9-(K28/J28-1),"") -> 0.12746615 | ... M40: =IFERROR(M9-(M28/L28-1),"") -> 0.093090038
B42: ASSET QUALITY
B43: Credit Cost % (Impairment on Fin. Instruments ÷ Avg. Loans) | D43: =IFERROR('Profit & Loss'!D20/D24,"") -> 0.0059181303 | E43: =IFERROR('Profit & Loss'!E20/E24,"") -> -0.0096131498 | F43: =IFERROR('Profit & Loss'!F20/F24,"") -> 0.0038652954 | G43: =IFERROR('Profit & Loss'!G20/G24,"") -> 0.053274882 | H43: =IFERROR('Profit & Loss'!H20/H24,"") -> 0.024910868 | I43: ='Credit Cost Forecast'!D10 -> 0.022 | J43: ='Credit Cost Forecast'!E10 -> 0.019 | K43: ='Credit Cost Forecast'!F10 -> 0.017 | L43: ='Credit Cost Forecast'!G10 -> 0.016 | M43: ='Credit Cost Forecast'!H10 -> 0.015
B44: Gross NPA % (linked, company-disclosed) | D44: ='Business Performance Scorecard'!D177 -> 3.29 | E44: ='Business Performance Scorecard'!E177 -> 1.44 | F44: ='Business Performance Scorecard'!F177 -> 1.16 | G44: ='Business Performance Scorecard'!G177 -> 1.84 | H44: ='Business Performance Scorecard'!H177 -> 1.44 | I44: ='Credit Cost Forecast'!D6*100 -> 1.35 | J44: ='Credit Cost Forecast'!E6*100 -> 1.3 | K44: ='Credit Cost Forecast'!F6*100 -> 1.25 | L44: ='Credit Cost Forecast'!G6*100 -> 1.2 | M44: ='Credit Cost Forecast'!H6*100 -> 1.15
...

Sheet C - Planning & Forecasting
B2: C | C2: SECTION C — PLANNING & FORECASTING | F2: ⌂ Home
C4: The driver-based FY2027E–FY2031E forecast engine. No line here is a growth-percentage guess — every projection builds from an operating driver, with each assumption cited to a disclosed figure or explicitly marked illustrative.
B6: WHAT THIS SECTION COVERS
C7: • Revenue built as Average AUM × Yield, plus fee and other income
C8: • Funding: borrowings scaled to AUM at a leverage consistent with CRAR headroom, and the cost-of-funds glide path
C9: • Treasury and liquidity: borrowing mix and implied cost of funds cross-check
C10: • Credit cost: GNPA/NNPA/PCR glide path converting to a provisioning charge
C11: • Operating costs forecast by category on their own drivers, plus capex and depreciation roll-forward
B13: SHEETS IN THIS SECTION
B14: Ref | C14: Sheet | D14: What it does
B15: C1 | C15: Assumptions | D15: All macro and strategic forecast inputs, each with rationale and source — the single editable entry point for the forecast
B16: C2 | C16: Revenue Forecast | D16: Average AUM × Yield = Interest Income; fee and other income as % of AUM
B17: C3 | C17: Funding Forecast | D17: Borrowings, cost of funds and interest expense
B18: C4 | C18: Treasury | D18: Borrowing mix, cost of borrowing and liquidity position
B19: C5 | C19: Credit Cost Forecast | D19: GNPA, NNPA, PCR glide path and the resulting credit cost
B20: C6 | C20: Operating Cost Forecast | D20: Cost lines forecast by category on their own drivers, feeding the cost-to-income ratio
B21: C7 | C21: Regulatory Capital | D21: RWA → CRAR → capital requirement; shows the growth plan is capital-constrained and sizes the equity need
B22: C8 | C22: CapEx & Depreciation Schedule | D22: Net block roll-forward feeding D&A into the P&L, Cash Flow and Balance Sheet

Sheet Assumptions
B1: POONAWALLA FINCORP LIMITED — Forecast Assumptions (FY2027E–FY2031E) | L1: ⌂ Home
B2: Macro assumptions are calibrated to FY2026 disclosed actuals and RBI's medium-term policy targets (illustrative glide, not an official RBI/IMF forecast). Strategic assumptions (branch, productivity) are calibrated to the Company's own disclosed FY2026 network and headcount. All feed the Business Drivers sheet.
B4: Particulars | C4: FY2026A | D4: FY2027E | E4: FY2028E | F4: FY2029E | G4: FY2030E | H4: FY2031E | J4: Rationale / Source
B6: MACRO ASSUMPTIONS
B7: Real GDP Growth % | C7: 0.077 | D7: 0.07 | E7: 0.068 | F7: 0.067 | G7: 0.066 | H7: 0.065 | J7: FY2026A: "GDP growth improved to 7.7% in FY26 from 7.1% in FY25" (AR FY2026 pg.20). Forecast years: illustrative normalisation toward India's medium-term potential growth (~6.5%); not an official RBI/IMF projection.
B8: Inflation (CPI) % | C8: 0.018 | D8: 0.035 | E8: 0.04 | F8: 0.04 | G8: 0.04 | H8: 0.04 | J8: FY2026A: "Inflation cooled off to 1.8% during the year" (AR FY2026 pg.20). Forecast years: illustrative normalisation toward RBI's 4% medium-term CPI target (mid-point of the 2-6% band).
B9: RBI Repo Rate % (year-end) | C9: 0.0525 | D9: 0.0525 | E9: 0.055 | F9: 0.0575 | G9: 0.0575 | H9: 0.0575 | J9: FY2026A: "RBI reduced the repo rate by a cumulative 100 bps, bringing it down to 5.25% by December 31, 2025" (AR FY2026 pg.20). Forecast years: illustrative mild normalisation as inflation firms toward target; not an official RBI forecast.
B10: NBFC Industry AUM / Credit Growth % | D10: 0.175 | E10: 0.16 | F10: 0.15 | G10: 0.145 | H10: 0.14 | J10: "AUM of NBFCs are expected to grow steadily at 16-19% during FY26 and FY27... sector's AUM is projected to cross ₹30 Lakh Crore by March 2027" (AR FY2026 pg.20, source: CRISIL). FY28-31: illustrative taper toward a long-run industry average (~14%). Used as a cross-check on Company AUM growth, not a direct driver.
B12: STRATEGIC / OPERATING ASSUMPTIONS
B13: Net Branch Additions (count, p.a.) | D13: 150 | E13: 130 | F13: 100 | G13: 90 | H13: 80 | J13: Decelerating expansion pace as the network matures. FY2026A base: "500+ branches (incl. 400 gold loan branches)" (AR FY2026 pg.2). Gold Loan branch build-out was itself rapid in FY26 (+400); assumed to moderate as coverage scales.
B14: Employees per Branch (avg., productivity ratio) | C14: 11.72 | D14: 11.5 | E14: 11.2 | F14: 11 | G14: 10.8 | H14: 10.6 | J14: FY2026A actual: 5,860 employees ÷ 500 branches = 11.72 (AR FY2026 pg.4 and pg.2, KPIs & Ratios tab). Gradual improvement assumed as digital/AI-led underwriting and collections reduce headcount intensity per branch (AR FY2026 pg.24-26 on AI/automation initiatives).
B15: Wage Inflation % p.a. (cost per employee growth) | D15: 0.08 | E15: 0.08 | F15: 0.08 | G15: 0.075 | H15: 0.075 | J15: Illustrative assumption consistent with typical Indian BFSI wage inflation (~8%), moderating slightly as inflation normalises toward the RBI target (row 8).
B16: Effective Tax Rate % | C16: 0.2517 | D16: 0.2517 | E16: 0.2517 | F16: 0.2517 | G16: 0.2517 | H16: 0.2517 | J16: Standard Indian corporate tax rate under Section 115BAA (25.17% incl. surcharge & cess), applicable to most Indian companies opting for the lower tax regime.
